Workbook

Sheet Alumni AG
A1: 🌱 Alumni Gaea21 pour AG — 510 personnes
A2: ID | B2: Prénom | C2: Nom | D2: Année sortie | E2: Fonction Gaea21 | F2: Type contrat | G2: Date entrée | H2: Date sortie | I2: Statut Alumni | J2: — LinkedIn — | K2: Poste actuel | L2: Entreprise | M2: Ville | N2: Pays | O2: Secteur | P2: URL LinkedIn | Q2: Statut enrich. | R2: Notes
A3: 2 | B3: Khaled | C3: ABDELHAK | D3: 2023 | E3: IT | F3: Bénévole | G3: 2023-03-02 | H3: 2023-09-02 | Q3: ⬜ À enrichir
A4: 6 | B4: Conan Sherlock | C4: ABOUTOU | D4: 2023 | E4: Statistiques | F4: Bénévole | G4: 2023-02-08 | H4: 2023-11-03 | Q4: ⬜ À enrichir
A5: 8 | B5: Imane | C5: ACHOURI | D5: 2023 | E5: scientifique | F5: Bénévole | G5: 2023-05-10 | H5: 2023-11-17 | Q5: ⬜ À enrichir
A6: 9 | B6: Manuela | C6: ACOSTA | D6: 2023 | E6: RH | F6: Bénévole | G6: 2023-03-01 | H6: 2023-06-02 | Q6: ⬜ À enrichir
A7: 10 | B7: Annick | C7: ADOUKONOU | D7: 2023 | E7: GCBO / Restuaration durable | F7: Bénévole | G7: 2023-08-07 | H7: 2023-12-15 | Q7: ⬜ À enrichir
A8: 12 | B8: Nour | C8: AFFES | D8: 2023 | E8: IT | F8: Conventioné | G8: 2022-06-09 | H8: 2023-02-03 | Q8: ⬜ À enrichir
A9: 16 | B9: Pélé Patrice | C9: AHOUDJI | D9: 2023 | E9: CCDSP - smart cities, recherche et AG recherche | F9: Bénévole | G9: 2023-10-10 | H9: 2024-05-03 | Q9: ⬜ À enrichir
A10: 17 | B10: Mame Lala | C10: AICHA DIENG | D10: 2023 | E10: Statistiques | F10: Conventioné | G10: 2023-12-11 | H10: 2024-07-05 | Q10: ⬜ À enrichir
A11: 20 | B11: Tolgahan | C11: ALGUL | D11: 2023 | E11: Partenariat et expension | F11: Conventioné | G11: 2023-02-05 | H11: 2023-03-08 | I11: Non | Q11: ⬜ À enrichir
A12: 24 | B12: Emmanuelle | C12: AMBERT | D12: 2023 | E12: Traduction | F12: Conventioné | G12: 2023-04-11 | H12: 2023-08-10 | Q12: ⬜ À enrichir
A13: 26 | B13: Gary | C13: AMECIA | D13: 2023 | E13: Budget / osez entrepreunariat | F13: Conventioné | G13: 2023-01-16 | H13: 2023-07-14 | Q13: ⬜ À enrichir
A14: 28 | B14: Carmen | C14: AMOUH | D14: 2023 | E14: rh | F14: Bénévole | G14: 2023-01-18 | H14: 2025-12-14 | I14: Alumni gratuit | Q14: ⬜ À enrichir
A15: 30 | B15: Holy Marlène | C15: ANDRIAMASY | D15: 2023 | E15: Data analyst | F15: Bénévole | G15: 2023-01-16 | H15: 2023-04-14 | Q15: ⬜ À enrichir
A16: 34 | B16: Arzu | C16: ARDICLI | D16: 2023 | E16: Cartographie/ eco mobilité | F16: Bénévole | G16: 2022-12-05 | H16: 2023-06-09 | Q16: ⬜ À enrichir
A17: 38 | B17: Foteini | C17: ATHANASOPOULOU | D17: 2023 | E17: Eco-conso scientifique | F17: Bénévole | G17: 2022-11-09 | H17: 2023-05-26 | Q17: ⬜ À enrichir
A18: 40 | B18: Edouard | C18: AUSSEDAT | D18: 2023 | E18: Formateur pédagogique | F18: Bénévole | G18: 2022-08-30 | H18: 2023-03-17 | I18: Alumni gratuit | Q18: ⬜ À enrichir
A19: 44 | B19: Arhamatou | C19: Abdourhamane | D19: 2023 | E19: Budget/ Pré-Analayse | F19: Conventioné | G19: 2023-06-13 | H19: 2023-09-15 | Q19: ⬜ À enrichir
A20: 52 | B20: Kumud | C20: BADERIYA | D20: 2023 | E20: PAC/ Green id | F20: Bénévole | G20: 2022-11-03 | H20: 2023-05-26 | Q20: ⬜ À enrichir
A21: 53 | B21: AROUA | C21: BALAYIRA | D21: 2023 | E21: Budget Admin/ osez l'entrpreunariat | F21: Conventioné | G21: 2023-06-12 | H21: 2023-12-15 | Q21: ⬜ À enrichir
A22: 57 | B22: Aurélie | C22: BARBIER | D22: 2023 | E22: Coach | F22: Bénévole | G22: 2023-04-19 | H22: 2023-10-20 | Q22: ⬜ À enrichir
A23: 58 | B23: Benjamin | C23: BARDET | D23: 2023 | E23: IT | F23: Conventioné | G23: 2023-02-03 | H23: 2023-05-19 | Q23: ⬜ À enrichir
A24: 59 | B24: Mahdi | C24: BECHIM | D24: 2023 | E24: RH | F24: Bénévole | G24: 2023-06-28 | H24: 2023-09-29 | Q24: ⬜ À enrichir
A25: 62 | B25: Bradley | C25: BELINGA | D25: 2023 | E25: CM/ Branding/ Partenariat | F25: Bénévole | G25: 2023-03-07 | H25: 2023-09-08 | Q25: ⬜ À enrichir
A26: 67 | B26: Hafedh | C26: BEN DHIA | D26: 2023 | E26: IT | F26: Bénévole | G26: 2023-06-15 | H26: 2023-09-15 | Q26: ⬜ À enrichir
A27: 70 | B27: Oumayma | C27: BEN RACHED | D27: 2023 | E27: éco geste et Scientifique | F27: Bénévole | G27: 2023-04-03 | H27: 2023-10-06 | Q27: ⬜ À enrichir
A28: 71 | B28: Amira | C28: BEN SOLTANE | D28: 2023 | E28: Statistiques/ Formation | F28: Conventioné | G28: 2023-12-12 | H28: 2024-05-31 | Q28: ⬜ À enrichir
A29: 72 | B29: Rayan | C29: BENGUEDIH | D29: 2023 | E29: Statistiques | F29: Bénévole | G29: 2023-04-04 | H29: 2023-08-04 | I29: Alumni gratuit | Q29: ⬜ À enrichir
A30: 74 | B30: Enzo | C30: BIANCU | D30: 2023 | E30: CM/ Partenariat | F30: Conventioné | G30: 2023-01-31 | H30: 2023-07-28 | Q30: ⬜ À enrichir
A31: 75 | B31: Aïcha | C31: BIBI | D31: 2023 | E31: IT | F31: Conventioné | G31: 2023-04-20 | H31: 2023-09-20 | Q31: ⬜ À enrichir
A32: 78 | B32: Bouwèreou | C32: BIGNAN-KAGOMNA | D32: 2023 | E32: GCBO/ architecture /publication | F32: Bénévole | G32: 2023-07-08 | H32: 2023-11-10 | Q32: ⬜ À enrichir
A33: 80 | B33: Andy | C33: BLONDELLE | D33: 2023 | E33: IT | F33: Conventioné | G33: 2023-01-03 | H33: 2023-04-14 | Q33: ⬜ À enrichir
A34: 81 | B34: Lobna | C34: BOUALLEGUE | D34: 2023 | E34: IT | F34: Conventioné | G34: 2023-05-04 | H34: 2023-11-03 | Q34: ⬜ À enrichir
A35: 84 | B35: Julie | C35: BOURGERY | D35: 2023 | E35: RH | F35: Bénévole | G35: 2022-04-06 | H35: 2022-10-07 | Q35: ⬜ À enrichir
A36: 85 | B36: Anais | C36: BRANDT | D36: 2023 | E36: Coach | F36: Bénévole | G36: 2023-05-24 | H36: 2023-08-25 | Q36: ⬜ À enrichir
A37: 86 | B37: Jayson | C37: BREMENT | D37: 2023 | E37: IT | F37: Conventioné | G37: 2023-08-24 | H37: 2023-11-15 | Q37: ⬜ À enrichir
A38: 87 | B38: Bénedicte | C38: BROCHU | D38: 2023 | E38: Coach | F38: Bénévole | G38: 2022-09-12 | H38: 2023-04-07 | Q38: ⬜ À enrichir
A39: 89 | B39: Viviane | C39: BRUNET | D39: 2023 | E39: RH | F39: Conventioné | G39: 2023-04-26 | H39: 2023-07-28 | Q39: ⬜ À enrichir
A40: 91 | B40: Katarina | C40: BUKVIC | D40: 2023 | E40: RH | F40: Conventioné | G40: 2023-03-13 | H40: 2023-06-16 | Q40: ⬜ À enrichir
...

Sheet 📊 Stats
A1: 📊 Statistiques (auto-calculées)
A3: 🎯 VOLUMES CLÉS | D3: 🌍 PAR PAYS (post-enrichissement)
A4: Total alumni dans la base | B4: =COUNTA('Alumni AG'!B3:B512) | D4: Pays | E4: Nombre
A5: Enrichis via LinkedIn | B5: =COUNTIF('Alumni AG'!Q3:Q512,"✅ Enrichi") | D5: Suisse | E5: =COUNTIF('Alumni AG'!N3:N512,"Suisse")
A6: À enrichir | B6: =COUNTIF('Alumni AG'!Q3:Q512,"⬜ À enrichir") | D6: France | E6: =COUNTIF('Alumni AG'!N3:N512,"France")
A7: Introuvables LinkedIn | B7: =COUNTIF('Alumni AG'!Q3:Q512,"❌ Introuvable sur LinkedIn") | D7: Allemagne | E7: =COUNTIF('Alumni AG'!N3:N512,"Allemagne")
D8: Belgique | E8: =COUNTIF('Alumni AG'!N3:N512,"Belgique")
D9: Italie | E9: =COUNTIF('Alumni AG'!N3:N512,"Italie")
A10: 📅 PAR ANNÉE DE SORTIE | D10: Royaume-Uni | E10: =COUNTIF('Alumni AG'!N3:N512,"Royaume-Uni")
A11: Année | B11: Nombre | D11: Espagne | E11: =COUNTIF('Alumni AG'!N3:N512,"Espagne")
A12: 2023 | B12: =COUNTIF('Alumni AG'!D3:D512,2023) | D12: Portugal | E12: =COUNTIF('Alumni AG'!N3:N512,"Portugal")
A13: 2024 | B13: =COUNTIF('Alumni AG'!D3:D512,2024) | D13: États-Unis | E13: =COUNTIF('Alumni AG'!N3:N512,"États-Unis")
A14: 2025 | B14: =COUNTIF('Alumni AG'!D3:D512,2025) | D14: Canada | E14: =COUNTIF('Alumni AG'!N3:N512,"Canada")
A15: 2026 | B15: =COUNTIF('Alumni AG'!D3:D512,2026) | D15: Brésil | E15: =COUNTIF('Alumni AG'!N3:N512,"Brésil")
D16: Kenya | E16: =COUNTIF('Alumni AG'!N3:N512,"Kenya")
D17: Sénégal | E17: =COUNTIF('Alumni AG'!N3:N512,"Sénégal")
D18: Maroc | E18: =COUNTIF('Alumni AG'!N3:N512,"Maroc")
D19: Tunisie | E19: =COUNTIF('Alumni AG'!N3:N512,"Tunisie")
D20: Côte d'Ivoire | E20: =COUNTIF('Alumni AG'!N3:N512,"Côte d'Ivoire")
D21: Burkina Faso | E21: =COUNTIF('Alumni AG'!N3:N512,"Burkina Faso")
D22: Algérie | E22: =COUNTIF('Alumni AG'!N3:N512,"Algérie")
D23: Autre | E23: =COUNTIF('Alumni AG'!N3:N512,"Autre")
D26: 🎯 PAR SECTEUR
D27: Secteur | E27: Nombre
D28: Environnement / Climat | E28: =COUNTIF('Alumni AG'!O3:O512,"Environnement / Climat")
D29: Finance durable / ESG | E29: =COUNTIF('Alumni AG'!O3:O512,"Finance durable / ESG")
D30: Conseil / Audit | E30: =COUNTIF('Alumni AG'!O3:O512,"Conseil / Audit")
D31: Éducation / Recherche | E31: =COUNTIF('Alumni AG'!O3:O512,"Éducation / Recherche")
D32: ONG / Associatif | E32: =COUNTIF('Alumni AG'!O3:O512,"ONG / Associatif")
D33: Secteur public | E33: =COUNTIF('Alumni AG'!O3:O512,"Secteur public")
D34: Entreprise privée | E34: =COUNTIF('Alumni AG'!O3:O512,"Entreprise privée")
D35: Tech / Data | E35: =COUNTIF('Alumni AG'!O3:O512,"Tech / Data")
D36: Santé | E36: =COUNTIF('Alumni AG'!O3:O512,"Santé")
D37: Culture / Média | E37: =COUNTIF('Alumni AG'!O3:O512,"Culture / Média")
D38: Autre | E38: =COUNTIF('Alumni AG'!O3:O512,"Autre")

Sheet 🎯 Priorités
A1: 🎯 Alumni prioritaires pour enrichissement LinkedIn
A2: Stratégie: prioriser les alumni 2024-2025, qui sont partis récemment et sont le plus probablement visibles sur LinkedIn avec un poste actuel identifiable. Commence par le haut de cette liste.
A3: # | B3: Prénom | C3: Nom | D3: Année | E3: Fonction
A4: 1 | B4: Angela | C4: ABANKWA | D4: 2024 | E4: RH
A5: 2 | B5: Asmaà | C5: ABIDERRAHMANE | D5: 2024 | E5: IT
A6: 3 | B6: Andre | C6: ABLI | D6: 2024 | E6: Juridique
A7: 4 | B7: Johanna | C7: AEBI | D7: 2024 | E7: RH
A8: 5 | B8: Gérald | C8: AGBOTI | D8: 2024 | E8: Collaboteur agriculture durable
A9: 6 | B9: Yassh | C9: AGORO | D9: 2024 | E9: Data scientist
A10: 7 | B10: Yousra | C10: AL NASIR | D10: 2024 | E10: Coordinatrice recherche agriculture Durable
A11: 8 | B11: Jules-vianney | C11: ALIANA FOUDA | D11: 2024 | E11: Ingénieur éléctromagnétique
A12: 9 | B12: Alice | C12: ALVES PINTO | D12: 2024 | E12: Traductrice
A13: 10 | B13: Claire | C13: AMBLARD | D13: 2024 | E13: Design
A14: 11 | B14: Claire | C14: AMORY | D14: 2024 | E14: Coordinatrice GCBO
A15: 12 | B15: Anna-Maria | C15: ANNONAY | D15: 2024 | E15: Traductrice
... A153: 150 | B153: Alicx Maryse | C153: RABEMAHARAVO | D153: 2024 | E153: Coordinateur GCBO
